<?xml version='1.0'?>

<robot name="my_bot" xmlns:xacro="http://www.ros.org/wiki/xacro">
  <xacro:include filename="$(find my_bot)/urdf/my_bot.gazebo"/>
  <xacro:include filename="$(find my_bot)/urdf/common_properties.xacro"/>

  <link name="robot_footprint"></link>

  <joint name="robot_footprint_joint" type="fixed">
    <parent link="robot_footprint"/>
    <child link="chasis" />
    <origin xyz="0 0 0.0122" rpy="0 0 0"/>
  </joint>

  <link name="chasis">
    <visual>
      <origin xyz="-0.035 0 0.0" rpy="0 0 0"/>
      <geometry>
        <mesh filename="package://my_bot/meshes/platform_mesh.stl" scale="0.001 0.001 0.001"/>
      </geometry>
      <material name="light_black"/>
    </visual>

    <collision>
      <origin xyz="-0.035 0 0.02901" rpy="0 0 0"/>
      <geometry>
        <box size="0.220 0.220 0.05802"/>
      </geometry>
    </collision>
    
    <inertial>
      <origin xyz="0 0 0" rpy="0 0 0"/>
    <mass value="0.881e+00"/>
    <inertia ixx="3.0e-03" ixy="0" ixz="0"
         iyy="3.0e-03" iyz="0"
         izz="6.0e-03" />
    </inertial>
  </link>


  

  <link name="wheel_left_link">
    <visual>
      <origin xyz="0 0 -0.0085" rpy="0 1.57 0"/>
      <geometry>
        <mesh filename="package://my_bot/meshes/wheel_mesh.stl" scale="0.001 0.001 0.001"/>
      </geometry>
      <material name="dark"/>
    </visual>

    <collision>
      <origin xyz="0 0 0.0045" rpy="0 0 0"/>
      <geometry>
        <cylinder length="0.026" radius="0.0325"/>
      </geometry>
    </collision>

    <inertial>
      <origin xyz="0 0 0" />
    <mass value="3.3e-02" />
      <inertia ixx="1e-05" ixy="0.0" ixz="0.0"
               iyy="1e-05" iyz="0.0"
               izz="1e-05" />
    </inertial>
  </link>

  

  <link name="wheel_right_link">
  <visual>
    <origin xyz="0 0 0.0085" rpy="0 -1.57 0"/>
    <geometry>
    <mesh filename="package://my_bot/meshes/wheel_mesh.stl" scale="0.001 0.001 0.001"/>
    </geometry>
    <material name="dark"/>
  </visual>

  <collision>
    <origin xyz="0 0 -0.0045" rpy="0 0 0"/>
    <geometry>
    <cylinder length="0.026" radius="0.0325"/>
    </geometry>
  </collision>

  <inertial>
    <origin xyz="0 0 0" />
    <mass value="3.3e-02" />
      <inertia ixx="1e-05" ixy="0.0" ixz="0.0"
               iyy="1e-05" iyz="0.0"
               izz="1e-05" />
    </inertial>
  </link>

  

  <link name="caster_back_right_link">
  <visual>
    <origin xyz="0 0 0" rpy="0 0 0"/>
    <geometry>
    <mesh filename="package://my_bot/meshes/caster_ball_mesh.stl" scale="0.001 0.001 0.001"/>
    </geometry>
    <material name="white"/>
  </visual>
  <collision>
    <origin xyz="0.000575 0 0" rpy="0 0 0"/>
    <geometry>
    <box size="0.01385 0.013 0.013"/>
    </geometry>
  </collision>

  <inertial>
    <origin xyz="0 0 0" />
    <mass value="8.37e-03" />
      <inertia ixx="1e-03" ixy="0.0" ixz="0.0"
               iyy="1e-03" iyz="0.0"
               izz="1e-03" />
    </inertial>
  </link>

  <link name="caster_back_left_link">
  <visual>
    <origin xyz="0 0 0" rpy="0 0 0"/>
    <geometry>
    <mesh filename="package://my_bot/meshes/caster_ball_mesh.stl" scale="0.001 0.001 0.001"/>
    </geometry>
    <material name="white"/>
  </visual>
  <collision>
    <origin xyz="0.000575 0 0" rpy="0 0 0"/>
    <geometry>
    <box size="0.01385 0.013 0.013"/>
    </geometry>
  </collision>

  <inertial>
    <origin xyz="0 0 0" />
    <mass value="8.37e-03" />
      <inertia ixx="1e-03" ixy="0.0" ixz="0.0"
               iyy="1e-03" iyz="0.0"
               izz="1e-03" />
    </inertial>
  </link>

  <!-- Camera Link -->

  <link name="camera">

    <inertial>
      <mass value="0.1"/>
      <origin xyz="0 0 0" rpy="0 0 0"/>
      <inertia
          ixx="1e-6" ixy="0" ixz="0"
          iyy="1e-6" iyz="0"
          izz="1e-6"
      />
    </inertial>
    <visual>
      <geometry>
        <box size="0.025 0.025 0.025"/>
      </geometry>
      <origin xyz="0 0 0" rpy="0 0 0"/>
      <material name="red">
        <color rgba="0 0 1 1"/>
      </material>
    </visual>
    <collision>
      <geometry>
        <box size="0.025 0.025 0.025"/>
      </geometry>
      <origin xyz="0 0 0" rpy="0 0 0"/>
    </collision>
  </link>

  <!-- Hokuyo Link -->

  <link name="hokuyo">

    <inertial>
      <mass value="0.1"/>
      <origin xyz="0 0 0" rpy="0 0 0"/>
      <inertia
          ixx="1e-6" ixy="0" ixz="0"
          iyy="1e-6" iyz="0"
          izz="1e-6"
      />
    </inertial>
    <visual>
      <geometry>
        <mesh filename="package://my_bot/meshes/hokuyo.dae"/>
      </geometry>
      <origin xyz="0 0 0" rpy="0 0 0"/>
    </visual>
    <collision>
      <geometry>
        <box size="0.05 0.05 0.05"/>
      </geometry>
      <origin xyz="0 0 0" rpy="0 0 0"/>
    </collision>
  </link>

  <!-- Joints -->

  <joint name="wheel_right_joint" type="continuous">
    <parent link="chasis"/>
    <child link="wheel_right_link"/>
    <origin xyz="0.015 0.09975 0.0188" rpy="-1.57 0 0"/>
    <axis xyz="0 0 1"/>
  </joint>

  <joint name="wheel_left_joint" type="continuous">
    <parent link="chasis"/>
    <child link="wheel_left_link"/>
    <origin xyz="0.015 -0.09975 0.0188" rpy="-1.57 0 0"/>
    <axis xyz="0 0 1"/>
  </joint>

  <joint name="caster_back_right_joint" type="fixed">
  <parent link="chasis"/>
  <child link="caster_back_right_link"/>
  <origin xyz="-0.133 0.053 -0.0075" rpy="-1.57 0 0"/>
  </joint>

  <joint name="caster_back_left_joint" type="fixed">
  <parent link="chasis"/>
  <child link="caster_back_left_link"/>
  <origin xyz="-0.133 -0.053 -0.0075" rpy="-1.57 0 0"/>
  </joint>



  <joint type="fixed" name="camera_joint">
    <origin xyz="-0.12 0 0.075" rpy="0 0 3.14"/>
    <child link="camera"/>
    <parent link="chasis"/>
  </joint>

  <joint type="fixed" name="hokuyo_joint">
    <origin xyz="0.02 0 0.1" rpy="0 0 3.14"/>
    <child link="hokuyo"/>
    <parent link="chasis"/>
  </joint>

</robot>